<mujocoinclude>
    <body name="base_link" pos="0.0 0.0 1.0725">
        <joint name="float_base" type="free"/>  
        <!--根据wh加的部分，不知道干什么用的-->
        <joint type='slide' axis='1 0 0' limited='false' />
        <joint type='slide' axis='0 1 0' limited='false' />
        <joint type='slide' axis='0 0 1' limited='false' />
        <joint type='ball' limited='false' />

        <inertial pos="-0.00477386 0.000185684 0.0904459" quat="0.998815 -0.000630432 0.048651 -0.000939497" mass="34.3" diaginertia="1.91346 1.27701 0.78769"/>
        <site name='imu' size='0.01' pos='0.0 0 0.0'/> <!--增加imu-->

        <geom type="mesh" contype="1" conaffinity="1" group="1" class="visualgeom"  density="0" rgba="1 0 0 1" mesh="base_link"/>
        <!--geom type="mesh" contype="0" conaffinity="0" group="1" rgba="1 0 0 1" mesh="base_link" /-->
        <geom type="mesh" rgba="1 0 0 1" mesh="base_link" />
        <body name="left_leg_roll_link" pos="-0.055 0.12 -0.19" quat="0.00660746 -0.707076 -0.00661265 0.707076">
            <inertial pos="0 0 0.08" quat="0.707107 0 0 0.707107" mass="2.7" diaginertia="0.005213 0.0052 0.003441" />
            <joint name="left_leg_roll_joint" pos="0 0 0" axis="0 0 1" limited="true" range="-2.5 0.12" />
            <geom type="mesh" contype="0" conaffinity="0" group="1" rgba="1 1 1 1" mesh="left_leg_roll_link" />
            <geom type="mesh" rgba="1 1 1 1" mesh="left_leg_roll_link" />
            <body name="left_leg_yaw_link" pos="0 0 -0.05" quat="0.707105 0 0.707108 0">
                <inertial pos="0 0 0" mass="2.7" diaginertia="0.0052 0.0052 0.0035935" />
                <joint name="left_leg_yaw_joint" pos="0 0 0" axis="0 0 1" limited="true" range="-0.5 0.5" />
                <geom type="mesh" contype="0" conaffinity="0" group="1" rgba="1 1 1 1" mesh="left_leg_yaw_link" />
                <geom type="mesh" rgba="1 1 1 1" mesh="left_leg_yaw_link" />
                <body name="left_leg_pitch_link" pos="0.02 0 0.05" quat="0.56841 -0.568412 -0.420605 -0.420607">
                    <inertial pos="0.19429 -0.0397208 0" quat="0 0.707107 0 0.707107" mass="8.7" diaginertia="0.12259 0.092251 0.041831" />
                    <joint name="left_leg_pitch_joint" pos="0 0 0" axis="0 0 1" limited="true" range="0 2" />
                    <geom type="mesh" contype="0" conaffinity="0" group="1" rgba="1 1 1 1" mesh="left_leg_pitch_link" />
                    <geom type="mesh" rgba="1 1 1 1" mesh="left_leg_pitch_link" />
                    <body name="left_knee_link" pos="0.39649 -0.07893 0" quat="0.0443446 -0.967623 0.248214 -0.0113752">
                        <inertial pos="0.129618 -0.0443853 0.00407623" quat="0 0.707107 0 0.707107" mass="3.0353" diaginertia="0.024364 0.0242 0.00702" />
                        <joint name="left_knee_joint" pos="0 0 0" axis="0.036684 0.083773 0.995809" limited="true" range="0 3" />
                        <geom type="mesh" contype="0" conaffinity="0" group="1" rgba="1 1 1 1" mesh="left_knee_link" />
                        <geom type="mesh" rgba="1 1 1 1" mesh="left_knee_link" />
                        <body name="left_ankle_pitch_link" pos="0.388854 0.00193333 0.0210517" quat="-0.0288761 -0.630176 0.775102 -0.0355169">
                            <inertial pos="0 0 0.0211403" quat="0.5 0.5 -0.5 0.5" mass="0.5612" diaginertia="0.00140938 0.00140938 0.00140938" />
                            <joint name="left_ankle_pitch_joint" pos="0 0 0" axis="0 0 1" limited="true" range="-0.6 0.6" />
                            <geom type="mesh" contype="0" conaffinity="0" group="1" rgba="1 1 1 1" mesh="left_ankle_pitch_link_big" />
                            <geom type="mesh" rgba="1 1 1 1" mesh="left_ankle_pitch_link_big" />
                            <body name="left_ankle_roll_link" pos="0 -0.02 0.0211403" quat="0.707076 -0.00662574 0.707076 -0.00662574">
                                <inertial pos="-0.272285 -0.0169888 0.025" quat="0.5 0.5 -0.5 0.5" mass="0.5612" diaginertia="0.00140938 0.00140938 0.00140938" />
                                <joint name="left_ankle_roll_joint" pos="0 0 0" axis="0 0 -1" limited="true" range="-0.2 0.2" />
                                <geom type="mesh" contype="0" conaffinity="0" group="1" rgba="1 1 1 1" mesh="left_ankle_roll_link_new" />
                                <geom type="mesh" rgba="1 1 1 1" mesh="left_ankle_roll_link_new" />
                            </body>
                        </body>
                    </body>
                </body>
            </body>
        </body>
        <body name="right_leg_roll_link" pos="-0.055 -0.12 -0.19" quat="0.707076 0.00661005 0.707076 0.00661005">
            <inertial pos="0 0 -0.08" quat="0.707107 0 0 0.707107" mass="2.7" diaginertia="0.005213 0.0052 0.003441" />
            <joint name="right_leg_roll_joint" pos="0 0 0" axis="0 0 1" limited="true" range="-2.5 0.12" />
            <geom type="mesh" contype="0" conaffinity="0" group="1" rgba="1 1 1 1" mesh="right_leg_roll_link" />
            <geom type="mesh" rgba="1 1 1 1" mesh="right_leg_roll_link" />
            <body name="right_leg_yaw_link" pos="0 0 0.05" quat="-2.59734e-06 0.707105 2.59735e-06 0.707108">
                <inertial pos="0 0 0" mass="2.7" diaginertia="0.0052 0.0052 0.0035935" />
                <joint name="right_leg_yaw_joint" pos="0 0 0" axis="0 0 -1" limited="true" range="-0.5 0.5" />
                <geom type="mesh" contype="0" conaffinity="0" group="1" rgba="1 1 1 1" mesh="right_leg_yaw_link" />
                <geom type="mesh" rgba="1 1 1 1" mesh="right_leg_yaw_link" />
                <body name="right_leg_pitch_link" pos="0.02 0 0.05" quat="0.56841 -0.568412 -0.420605 -0.420607">
                    <inertial pos="0.19429 -0.0397208 0" quat="0 0.707107 0 0.707107" mass="8.7" diaginertia="0.12259 0.092251 0.041831" />
                    <joint name="right_leg_pitch_joint" pos="0 0 0" axis="0 0 1" limited="true" range="0 2" />
                    <geom type="mesh" contype="0" conaffinity="0" group="1" rgba="1 1 1 1" mesh="right_leg_pitch_link" />
                    <geom type="mesh" rgba="1 1 1 1" mesh="right_leg_pitch_link" />
                    <body name="right_knee_link" pos="0.39649 -0.07893 0" quat="0.967623 -0.0443389 0.0113738 -0.248214">
                        <inertial pos="0.129618 0.0443853 0.00407623" quat="0 0.707107 0 0.707107" mass="3.0353" diaginertia="0.024364 0.0242 0.00702" />
                        <joint name="right_knee_joint" pos="0 0 0" axis="-0.036684 0.083773 -0.995809" limited="true" range="0 3" />
                        <geom type="mesh" contype="0" conaffinity="0" group="1" rgba="1 1 1 1" mesh="right_knee_link" />
                        <geom type="mesh" rgba="1 1 1 1" mesh="right_knee_link" />
                        <body name="right_ankle_pitch_link" pos="0.388854 0.00193333 0.0210517" quat="-0.0288761 0.630176 0.775102 0.0355169">
                            <inertial pos="0 0 0" quat="0.5 0.5 -0.5 0.5" mass="0.5612" diaginertia="0.00140938 0.00140938 0.00140938" />
                            <joint name="right_ankle_pitch_joint" pos="0 0 0" axis="0 0 -1" limited="true" range="-0.6 0.6" />
                            <geom type="mesh" contype="0" conaffinity="0" group="1" rgba="1 1 1 1" mesh="left_ankle_pitch_link_big" />
                            <geom type="mesh" rgba="1 1 1 1" mesh="left_ankle_pitch_link_big" />
                            <body name="right_ankle_roll_link" pos="0 0.02 0.0211403" quat="0.00662574 -0.707076 0.00662574 -0.707076">
                                <inertial pos="-0.00031842 -0.0169888 0.025" quat="0.5 0.5 -0.5 0.5" mass="0.5612" diaginertia="0.00140938 0.00140938 0.00140938" />
                                <joint name="right_ankle_roll_joint" pos="0 0 0" axis="0 0 1" limited="true" range="-0.2 0.2" />
                                <geom type="mesh" contype="0" conaffinity="0" group="1" rgba="1 1 1 1" mesh="right_ankle_roll_link_new" />
                                <geom type="mesh" rgba="1 1 1 1" mesh="right_ankle_roll_link_new" />
                            </body>
                        </body>
                    </body>
                </body>
            </body>
        </body>
        <body name="waist_roll_link" pos="-0.055 0 -0.14" quat="0.499998 0.5 0.500002 0.5">
            <inertial pos="0 0.046236 0.05576" quat="0.707107 0 0 0.707107" mass="2.7" diaginertia="0.005213 0.0052 0.003441" />
            <joint name="body_roll_joint" pos="0 0 0" axis="0 0 -1" limited="true" range="-0.5 0.5" />
            <geom type="mesh" contype="0" conaffinity="0" group="1" rgba="0.79216 0.81961 0.93333 1" mesh="waist_roll_link" />
            <geom type="mesh" rgba="0.79216 0.81961 0.93333 1" mesh="waist_roll_link" />
            <body name="body_link" pos="0 0.14 0.055" quat="-0.499604 0.500398 0.499602 0.500396">
                <inertial pos="0.007929 -1.40139e-07 0.145137" quat="1 -5.90508e-06 -2.21442e-05 -0.000930905" mass="27.6" diaginertia="1.44643 0.797994 0.735101" />
                <joint name="body_yaw_joint" pos="0 0 0" axis="0 0 1" limited="true" range="-1 1" />
                <geom type="mesh" contype="0" conaffinity="0" group="1" rgba="0 0 1 1" mesh="left_foot_ee_link" />
                <geom type="mesh" rgba="0 0 1 1" mesh="left_foot_ee_link" />
                <geom pos="0.010131 0.14 0.33" quat="0.707105 -0.707108 0 0" type="mesh" contype="0" conaffinity="0" group="1" rgba="1 1 1 1" mesh="left_shoulder_pitch_link" />
                <geom pos="0.010131 0.14 0.33" quat="0.707105 -0.707108 0 0" type="mesh" rgba="1 1 1 1" mesh="left_shoulder_pitch_link" />
                <geom pos="0.010131 0.19 0.33" quat="0.5004 0.499602 0.499602 0.500396" type="mesh" contype="0" conaffinity="0" group="1" rgba="1 1 1 1" mesh="left_shoulder_roll_link" />
                <geom pos="0.010131 0.19 0.33" quat="0.5004 0.499602 0.499602 0.500396" type="mesh" rgba="1 1 1 1" mesh="left_shoulder_roll_link" />
                <geom pos="0.0103699 0.189999 0.18" quat="-2.92507e-09 1 -3.67028e-06 0.000796327" type="mesh" contype="0" conaffinity="0" group="1" rgba="1 1 1 1" mesh="left_arm_yaw_link" />
                <geom pos="0.0103699 0.189999 0.18" quat="-2.92507e-09 1 -3.67028e-06 0.000796327" type="mesh" rgba="1 1 1 1" mesh="left_arm_yaw_link" />
                <geom pos="0.0106884 0.189999 -0.0199997" quat="0.707108 0.707105 -0.000565684 0.000560492" type="mesh" contype="0" conaffinity="0" group="1" rgba="1 1 1 1" mesh="left_arm_pitch_link" />
                <geom pos="0.0106884 0.189999 -0.0199997" quat="0.707108 0.707105 -0.000565684 0.000560492" type="mesh" rgba="1 1 1 1" mesh="left_arm_pitch_link" />
                <geom pos="0.010131 -0.14 0.33" quat="0.707105 0.707108 0 0" type="mesh" contype="0" conaffinity="0" group="1" rgba="1 1 1 1" mesh="right_shoulder_pitch_link" />
                <geom pos="0.010131 -0.14 0.33" quat="0.707105 0.707108 0 0" type="mesh" rgba="1 1 1 1" mesh="right_shoulder_pitch_link" />
                <geom pos="0.010131 -0.19 0.33" quat="-0.500396 -0.499605 0.499602 0.500396" type="mesh" contype="0" conaffinity="0" group="1" rgba="1 1 1 1" mesh="right_shoulder_roll_link" />
                <geom pos="0.010131 -0.19 0.33" quat="-0.500396 -0.499605 0.499602 0.500396" type="mesh" rgba="1 1 1 1" mesh="right_shoulder_roll_link" />
                <geom pos="0.0098932 -0.189999 0.18" quat="-0.707105 -0.000560492 -0.000563087 -0.707108" type="mesh" contype="0" conaffinity="0" group="1" rgba="1 1 1 1" mesh="right_arm_yaw_link" />
                <geom pos="0.0098932 -0.189999 0.18" quat="-0.707105 -0.000560492 -0.000563087 -0.707108" type="mesh" rgba="1 1 1 1" mesh="right_arm_yaw_link" />
                <geom pos="0.00957541 -0.19 -0.0199997" quat="-0.707107 -0.707107 -0.000561791 0.000561787" type="mesh" contype="0" conaffinity="0" group="1" rgba="1 1 1 1" mesh="right_arm_pitch_link" />
                <geom pos="0.00957541 -0.19 -0.0199997" quat="-0.707107 -0.707107 -0.000561791 0.000561787" type="mesh" rgba="1 1 1 1" mesh="right_arm_pitch_link" />
            </body>
        </body>
    </body>
</mujocoinclude>
