<?xml version="1.0" encoding="utf-8"?>
<!-- This URDF was automatically created by SolidWorks to URDF Exporter! Originally created by Stephen Brawner (brawner@gmail.com) 
     Commit Version: 1.6.0-4-g7f85cfe  Build Version: 1.6.7995.38578
     For more information, please see http://wiki.ros.org/sw_urdf_exporter -->
     <!--大脚-->
<robot
  name="cowa_humanoid">
  <mujoco>
  <compiler 
    meshdir="../meshes" 
    balanceinertia="true" 
    discardvisual="false" />
  </mujoco>
  <link
    name="base_link">
    <inertial>
      <origin
        xyz="-0.0961662823726544 -1.03511339119498E-09 -0.162578216580196"
        rpy="0 0 0" />
      <mass
        value="4" />
      <inertia
        ixx="0.0227"
        ixy="0"
        ixz="0"
        iyy="0.0056068"
        iyz="0"
        izz="0.020062" />
    </inertial>
    <visual>
      <origin
        xyz="0 0 0"
        rpy="0 0 0" />
      <geometry>
        <mesh
          filename="../meshes/base_link.STL" />
      </geometry>
      <material
        name="">
        <color
          rgba="1 0 0 1" />
      </material>
    </visual>
    <collision>
      <origin
        xyz="0 0 0"
        rpy="0 0 0" />
      <geometry>
        <mesh
          filename="../meshes/base_link.STL" />
      </geometry>
    </collision>
  </link>
  <!--===========================下肢线=================================-->
  <link
    name="left_leg_roll_link">
    <inertial>
      <origin
        xyz="8.10983225019157E-17 2.91433543964104E-16 0.0800000000000171"
        rpy="0 0 0" />
      <mass
        value="2.7" />
      <inertia
        ixx="0.0052"
        ixy="0"
        ixz="0"
        iyy="0.005213"
        iyz="0"
        izz="0.003441" />
    </inertial>
    <visual>
      <origin
        xyz="0 0 0"
        rpy="0 0 0" />
      <geometry>
        <mesh
          filename="../meshes/left_leg_roll_link.STL" />
      </geometry>
      <material
        name="">
        <color
          rgba="1 1 1 1" />
      </material>
    </visual>
    <collision>
      <origin
        xyz="0 0 0"
        rpy="0 0 0" />
      <geometry>
        <mesh
          filename="../meshes/left_leg_roll_link.STL" />
      </geometry>
    </collision>
  </link>
  <joint
    name="left_leg_roll_joint"
    type="revolute">
    <origin
      xyz="-0.055 0.12 -0.19"
      rpy="-1.5708 1.5521 1.5708" />
    <parent
      link="base_link" />
    <child
      link="left_leg_roll_link" />
    <axis
      xyz="0 0 1" />
    <limit
      lower="-2.5"
      upper="0.12"
      effort="100"
      velocity="3.14" />
  </joint>
  <link
    name="left_leg_yaw_link">
    <inertial>
      <origin
        xyz="1.3878E-17 -1.3878E-17 -2.6021E-18"
        rpy="0 0 0" />
      <mass
        value="2.7" />
      <inertia
        ixx="0.0052"
        ixy="0"
        ixz="0"
        iyy="0.0052"
        iyz="0"
        izz="0.0035935" />
    </inertial>
    <visual>
      <origin
        xyz="0 0 0"
        rpy="0 0 0" />
      <geometry>
        <mesh
          filename="../meshes/left_leg_yaw_link.STL" />
      </geometry>
      <material
        name="">
        <color
          rgba="1 1 1 1" />
      </material>
    </visual>
    <collision>
      <origin
        xyz="0 0 0"
        rpy="0 0 0" />
      <geometry>
        <mesh
          filename="../meshes/left_leg_yaw_link.STL" />
      </geometry>
    </collision>
  </link>
  <joint
    name="left_leg_yaw_joint"
    type="revolute">
    <origin
      xyz="0 0 -0.05"
      rpy="0 1.5708 0" />
    <parent
      link="left_leg_roll_link" />
    <child
      link="left_leg_yaw_link" />
    <axis
      xyz="0 0 1" />
    <limit
      lower="-0.5"
      upper="0.5"
      effort="100"
      velocity="3.14" />
  </joint>
  <link
    name="left_leg_pitch_link">
    <inertial>
      <origin
        xyz="0.194289718821747 -0.0397207882444419 2.35922392732846E-16"
        rpy="0 0 0" />
      <mass
        value="8.7" />
      <inertia
        ixx="0.041831"
        ixy="0"
        ixz="0"
        iyy="0.092251"
        iyz="0"
        izz="0.12259" />
    </inertial>
    <visual>
      <origin
        xyz="0 0 0"
        rpy="0 0 0" />
      <geometry>
        <mesh
          filename="../meshes/left_leg_pitch_link.STL" />
      </geometry>
      <material
        name="">
        <color
          rgba="1 1 1 1" />
      </material>
    </visual>
    <collision>
      <origin
        xyz="0 0 0"
        rpy="0 0 0" />
      <geometry>
        <mesh
          filename="../meshes/left_leg_pitch_link.STL" />
      </geometry>
    </collision>
  </link>
  <joint
    name="left_leg_pitch_joint"
    type="revolute">
    <origin
      xyz="0.02 0 0.05"
      rpy="-1.5708 -1.2741 0" />
    <parent
      link="left_leg_yaw_link" />
    <child
      link="left_leg_pitch_link" />
    <axis
      xyz="0 0 1" />
    <limit
      lower="0"
      upper="2"
      effort="250"
      velocity="2" />
  </joint>
  <link
    name="left_knee_link">
    <inertial>
      <origin
        xyz="0.129618 -0.044385301553616 0.00407623044892469"
        rpy="0 0 0" />
      <mass
        value="3.0353" />
      <inertia
        ixx="0.00702"
        ixy="0"
        ixz="0"
        iyy="0.0242"
        iyz="0"
        izz="0.024364" />
    </inertial>
    <visual>
      <origin
        xyz="0 0 0"
        rpy="0 0 0" />
      <geometry>
        <mesh
          filename="../meshes/left_knee_link.STL" />
      </geometry>
      <material
        name="">
        <color
          rgba="1 1 1 1" />
      </material>
    </visual>
    <collision>
      <origin
        xyz="0 0 0"
        rpy="0 0 0" />
      <geometry>
        <mesh
          filename="../meshes/left_knee_link.STL" />
      </geometry>
    </collision>
  </link>
  <joint
    name="left_knee_joint"
    type="revolute">
    <origin
      xyz="0.39649 -0.07893 0"
      rpy="-3.05 0 -0.50221" />
    <parent
      link="left_leg_pitch_link" />
    <child
      link="left_knee_link" />
    <axis
      xyz="0.036684 0.083773 0.99581" />
    <limit
      lower="0"
      upper="3"
      effort="250"
      velocity="1.8" />
      <!-- velocity="1.8" /> -->
  </joint>
  <link
    name="left_ankle_pitch_link">
    <inertial>
      <origin
        xyz="-3.46944695195361E-17 -1.11022302462516E-16 0.0211402934613541"
        rpy="0 0 0" />
      <mass
        value="0.5612" />
      <inertia
        ixx="0.001954"
        ixy="0"
        ixz="0"
        iyy="0.00012314"
        iyz="0"
        izz="0.002151" />
    </inertial>
    <visual>
      <origin
        xyz="0 0 0"
        rpy="0 0 0" />
      <geometry>
        <mesh
          filename="../meshes/left_ankle_pitch_link_big.STL" />
      </geometry>
      <material
        name="">
        <color
          rgba="1 1 1 1" />
      </material>
    </visual>
    <collision>
      <origin
        xyz="0 0 0"
        rpy="0 0 0" />
      <geometry>
        <mesh
          filename="../meshes/left_ankle_pitch_link_big.STL" />
      </geometry>
    </collision>
  </link>
  <joint
    name="left_ankle_pitch_joint"
    type="revolute">
    <origin
      xyz="0.388854 0.00193333361784048 0.0210517037019404"
      rpy="-3.12285195038096 -0.0896477341098247 -1.77716881310355" />
    <parent
      link="left_knee_link" />
    <child
      link="left_ankle_pitch_link" />
    <axis
      xyz="0 0 1" />
    <limit
      lower="-0.6"
      upper="0.6"
      effort="75"
      velocity="1.57" />
  </joint>
  <link
    name="left_ankle_roll_link">
    <inertial>
      <origin
        xyz="-0.27228480773617 -0.0169888487847696 0.025"
        rpy="0 0 0" />
      <mass
        value="0.5612" />
      <inertia
        ixx="0.001954"
        ixy="0"
        ixz="0"
        iyy="0.00012314"
        iyz="0"
        izz="0.002151" />
    </inertial>
    <visual>
      <origin
        xyz="0 0 0"
        rpy="0 0 0" />
      <geometry>
        <mesh
          filename="../meshes/left_ankle_roll_link_new.STL" />
      </geometry>
      <material
        name="">
        <color
          rgba="1 1 1 1" />
      </material>
    </visual>
    <collision>
      <origin
        xyz="0 0 0"
        rpy="0 0 0" />
      <geometry>
        <mesh
          filename="../meshes/left_ankle_roll_link_new.STL" />
      </geometry>
    </collision>
  </link>
  <joint
    name="left_ankle_roll_joint"
    type="revolute">
    <origin
      xyz="0 -0.0200000000000002 0.0211402934613541"
      rpy="-1.57079632679471 1.55205562358606 -1.57079632679471" />
    <parent
      link="left_ankle_pitch_link" />
    <child
      link="left_ankle_roll_link" />
    <axis
      xyz="0 0 -1" />
    <limit
      lower="-0.2"
      upper="0.2"
      effort="75"
      velocity="1.2" />
  </joint>
  <link
    name="right_leg_roll_link">
    <inertial>
      <origin
        xyz="1.6792E-14 -8.3267E-17 -0.08"
        rpy="0 0 0" />
      <mass
        value="2.7" />
      <inertia
        ixx="0.0052"
        ixy="0"
        ixz="0"
        iyy="0.005213"
        iyz="0"
        izz="0.003441" />
    </inertial>
    <visual>
      <origin
        xyz="0 0 0"
        rpy="0 0 0" />
      <geometry>
        <mesh
          filename="../meshes/right_leg_roll_link.STL" />
      </geometry>
      <material
        name="">
        <color
          rgba="1 1 1 1" />
      </material>
    </visual>
    <collision>
      <origin
        xyz="0 0 0"
        rpy="0 0 0" />
      <geometry>
        <mesh
          filename="../meshes/right_leg_roll_link.STL" />
      </geometry>
    </collision>
  </link>
  <joint
    name="right_leg_roll_joint"
    type="revolute">
    <origin
      xyz="-0.055 -0.12 -0.19"
      rpy="1.5708 1.5521 1.5708" />
    <parent
      link="base_link" />
    <child
      link="right_leg_roll_link" />
    <axis
      xyz="0 0 1" />
    <limit
      lower="-2.5"
      upper="0.12"
      effort="100"
      velocity="3.14" />
  </joint>
  <link
    name="right_leg_yaw_link">
    <inertial>
      <origin
        xyz="1.0131E-15 -8.3267E-17 -1.6859E-14"
        rpy="0 0 0" />
      <mass
        value="2.7" />
      <inertia
        ixx="0.0052"
        ixy="0"
        ixz="0"
        iyy="0.0052"
        iyz="0"
        izz="0.0035935" />
    </inertial>
    <visual>
      <origin
        xyz="0 0 0"
        rpy="0 0 0" />
      <geometry>
        <mesh
          filename="../meshes/right_leg_yaw_link.STL" />
      </geometry>
      <material
        name="">
        <color
          rgba="1 1 1 1" />
      </material>
    </visual>
    <collision>
      <origin
        xyz="0 0 0"
        rpy="0 0 0" />
      <geometry>
        <mesh
          filename="../meshes/right_leg_yaw_link.STL" />
      </geometry>
    </collision>
  </link>
  <joint
    name="right_leg_yaw_joint"
    type="revolute">
    <origin
      xyz="0 0 0.05"
      rpy="3.1416 -1.5708 0" />
    <parent
      link="right_leg_roll_link" />
    <child
      link="right_leg_yaw_link" />
    <axis
      xyz="0 0 -1" />
    <limit
      lower="-0.5"
      upper="0.5"
      effort="100"
      velocity="3.14" />
  </joint>
  <link
    name="right_leg_pitch_link">
    <inertial>
      <origin
        xyz="0.194289718821747 -0.0397207882444419 -2.08166817117217E-16"
        rpy="0 0 0" />
      <mass
        value="8.7" />
      <inertia
        ixx="0.041831"
        ixy="0"
        ixz="0"
        iyy="0.092251"
        iyz="0"
        izz="0.12259" />
    </inertial>
    <visual>
      <origin
        xyz="0 0 0"
        rpy="0 0 0" />
      <geometry>
        <mesh
          filename="../meshes/right_leg_pitch_link.STL" />
      </geometry>
      <material
        name="">
        <color
          rgba="1 1 1 1" />
      </material>
    </visual>
    <collision>
      <origin
        xyz="0 0 0"
        rpy="0 0 0" />
      <geometry>
        <mesh
          filename="../meshes/right_leg_pitch_link.STL" />
      </geometry>
    </collision>
  </link>
  <joint
    name="right_leg_pitch_joint"
    type="revolute">
    <origin
      xyz="0.02 0 0.05"
      rpy="-1.5708 -1.2741 0" />
    <parent
      link="right_leg_yaw_link" />
    <child
      link="right_leg_pitch_link" />
    <axis
      xyz="0 0 1" />
    <limit
      lower="-0."
      upper="2"
      effort="250"
      velocity="2" />
  </joint>
  <link
    name="right_knee_link">
    <inertial>
      <origin
        xyz="0.129618 0.0443853015536158 0.00407623044892474"
        rpy="0 0 0" />
      <mass
        value="3.0353" />
      <inertia
        ixx="0.00702"
        ixy="0"
        ixz="0"
        iyy="0.0242"
        iyz="0"
        izz="0.024364" />
    </inertial>
    <visual>
      <origin
        xyz="0 0 0"
        rpy="0 0 0" />
      <geometry>
        <mesh
          filename="../meshes/right_knee_link.STL" />
      </geometry>
      <material
        name="">
        <color
          rgba="1 1 1 1" />
      </material>
    </visual>
    <collision>
      <origin
        xyz="0 0 0"
        rpy="0 0 0" />
      <geometry>
        <mesh
          filename="../meshes/right_knee_link.STL" />
      </geometry>
    </collision>
  </link>
  <joint
    name="right_knee_joint"
    type="revolute">
    <origin
      xyz="0.39649 -0.07893 0"
      rpy="-0.091581 0 -0.50221" />
    <parent
      link="right_leg_pitch_link" />
    <child
      link="right_knee_link" />
    <axis
      xyz="-0.036684 0.083773 -0.99581" />
    <limit
      lower="0"
      upper="3"
      effort="250"
      velocity="1.8" />
      <!-- velocity="1.8" /> -->
  </joint>
  <link
    name="right_ankle_pitch_link">
    <inertial>
      <origin
        xyz="6.9389E-18 1.1102E-16 0"
        rpy="0 0 0" />
      <mass
        value="0.5612" />
      <inertia
        ixx="0.001954"
        ixy="0"
        ixz="0"
        iyy="0.00012314"
        iyz="0"
        izz="0.002151" />
    </inertial>
    <visual>
      <origin
        xyz="0 0 0"
        rpy="0 0 0" />
      <geometry>
        <mesh
          filename="../meshes/left_ankle_pitch_link_big.STL" />
      </geometry>
      <material
        name="">
        <color
          rgba="1 1 1 1" />
      </material>
    </visual>
    <collision>
      <origin
        xyz="0 0 0"
        rpy="0 0 0" />
      <geometry>
        <mesh
          filename="../meshes/left_ankle_pitch_link_big.STL" />
      </geometry>
    </collision>
  </link>
  <joint
    name="right_ankle_pitch_joint"
    type="revolute">
    <origin
      xyz="0.388854 0.00193333361784048 0.0210517037019404"
      rpy="3.12285195038096 -0.0896477341098247 1.77716881310355" />
    <parent
      link="right_knee_link" />
    <child
      link="right_ankle_pitch_link" />
    <axis
      xyz="0 0 -1" />
    <limit
      lower="-0.6"
      upper="0.6"
      effort="75"
      velocity="1.57" />
  </joint>
  <link
    name="right_ankle_roll_link">
    <inertial>
      <origin
        xyz="-0.000318420251686963 -0.0169888487847696 0.025"
        rpy="0 0 0" />
        <!-- xyz="-0.135641992803085 0.612073365196636 0.0228857190122595" -->
      <mass
        value="0.5612" />
      <inertia
        ixx="0.001954"
        ixy="0"
        ixz="0"
        iyy="0.00012314"
        iyz="0"
        izz="0.002151" />
    </inertial>
    <visual>
      <origin
        xyz="0 0 0"
        rpy="0 0 0" />
      <geometry>
        <mesh
          filename="../meshes/right_ankle_roll_link_new.STL" />
      </geometry>
      <material
        name="">
        <color
          rgba="1 1 1 1" />
      </material>
    </visual>
    <collision>
      <origin
        xyz="0 0 0"
        rpy="0 0 0" />
      <geometry>
        <mesh
          filename="../meshes/right_ankle_roll_link_new.STL" />
      </geometry>
    </collision>
  </link>
  <joint
    name="right_ankle_roll_joint"
    type="revolute">
    <origin
      xyz="0 0.0200000000000002 0.0211402934613541"
      rpy="-1.57079632679471 -1.55205562358606 -1.57079632679471" />
            <!-- xyz="0 -0.0200000000000002 0.0211402934613541"
      rpy="-1.57079632679471 1.55205562358606 -1.57079632679471" /> -->
    <parent
      link="right_ankle_pitch_link" />
    <child
      link="right_ankle_roll_link" />
    <axis
      xyz="0 0 1" />
    <limit
      lower="-0.2"
      upper="0.2"
      effort="75"
      velocity="1.2" />
  </joint>
<!--===========================上肢线=================================-->
  <link
    name="waist_roll_link">
    <inertial>
      <origin
        xyz="-5.2175E-18 0.046236 0.05576"
        rpy="0 0 0" />
      <mass
        value="2.7" />
      <inertia
        ixx="0.0052"
        ixy="0"
        ixz="0"
        iyy="0.005213"
        iyz="0"
        izz="0.003441" />
    </inertial>
    <visual>
      <origin
        xyz="0 0 0"
        rpy="0 0 0" />
      <geometry>
        <mesh
          filename="../meshes/waist_roll_link.STL" />
      </geometry>
      <material
        name="">
        <color
          rgba="0.79216 0.81961 0.93333 1" />
      </material>
    </visual>
    <collision>
      <origin
        xyz="0 0 0"
        rpy="0 0 0" />
      <geometry>
        <mesh
          filename="../meshes/waist_roll_link.STL" />
      </geometry>
    </collision>
  </link>
  <joint
    name="body_roll_joint"
    type="revolute">
    <origin
      xyz="-0.055 0 -0.14"
      rpy="1.5708 0 1.5708" />
    <parent
      link="base_link" />
    <child
      link="waist_roll_link" />
    <axis
      xyz="0 0 -1" />
    <limit
      lower="-0.5"
      upper="0.5"
      effort="75"
      velocity="1" />
  </joint>
  <link
    name="body_link">
    <inertial>
      <origin
        xyz="0 6.2215E-18 0.14563"
        rpy="0 0 0" />
      <mass
        value="6" />
      <inertia
        ixx="0.122300931455399"
        ixy="-6.27548739887208E-18"
        ixz="-2.56509389534329E-35"
        iyy="0.105155931455399"
        iyz="4.17705297827066E-18"
        izz="0.0676704666666667" />
    </inertial>
    <visual>
      <origin
        xyz="0 0 0"
        rpy="0 0 0" />
      <geometry>
        <mesh
          filename="../meshes/left_foot_ee_link.STL" />
      </geometry>
      <material
        name="">
        <color
          rgba="0 0 1 1" />
      </material>
    </visual>
    <collision>
      <origin
        xyz="0 0 0"
        rpy="0 0 0" />
      <geometry>
        <mesh
          filename="../meshes/left_foot_ee_link.STL" />
      </geometry>
    </collision>
  </link>
  <joint
    name="body_yaw_joint"
    type="revolute">
    <origin
      xyz="0 0.14 0.055"
      rpy="1.5708 -1.5708 3.14" />
    <parent
      link="waist_roll_link" />
    <child
      link="body_link" />
    <axis
      xyz="0 0 1" />
    <limit
      lower="-1"
      upper="1"
      effort="75"
      velocity="1" />
  </joint>
  <link
    name="left_shoulder_pitch_link">
    <inertial>
      <origin
        xyz="0 -1.11022302462516E-16 -0.05"
        rpy="0 0 0" />
      <mass
        value="2.7" />
      <inertia
        ixx="0.0052"
        ixy="0"
        ixz="0"
        iyy="0.0052"
        iyz="0"
        izz="0.0035935" />
    </inertial>
    <visual>
      <origin
        xyz="0 0 0"
        rpy="0 0 0" />
      <geometry>
        <mesh
          filename="../meshes/left_shoulder_pitch_link.STL" />
      </geometry>
      <material
        name="">
        <color
          rgba="1 1 1 1" />
      </material>
    </visual>
    <collision>
      <origin
        xyz="0 0 0"
        rpy="0 0 0" />
      <geometry>
        <mesh
          filename="../meshes/left_shoulder_pitch_link.STL" />
      </geometry>
    </collision>
  </link>
  <joint
    name="left_shoulder_pitch_joint"
    type="revolute">
    <origin
      xyz="0.010131 0.14 0.33"
      rpy="-1.5708 0 0" />
    <parent
      link="body_link" />
    <child
      link="left_shoulder_pitch_link" />
    <axis
      xyz="0 0 -1" />
    <limit
      lower="0"
      upper="0"
      effort="0"
      velocity="0" />
  </joint>
  <link
    name="left_shoulder_roll_link">
    <inertial>
      <origin
        xyz="-2.7756E-17 -0.05 0"
        rpy="0 0 0" />
      <mass
        value="2.7" />
      <inertia
        ixx="0.0052"
        ixy="0"
        ixz="0"
        iyy="0.0052"
        iyz="0"
        izz="0.0035935" />
    </inertial>
    <visual>
      <origin
        xyz="0 0 0"
        rpy="0 0 0" />
      <geometry>
        <mesh
          filename="../meshes/left_shoulder_roll_link.STL" />
      </geometry>
      <material
        name="">
        <color
          rgba="1 1 1 1" />
      </material>
    </visual>
    <collision>
      <origin
        xyz="0 0 0"
        rpy="0 0 0" />
      <geometry>
        <mesh
          filename="../meshes/left_shoulder_roll_link.STL" />
      </geometry>
    </collision>
  </link>
  <joint
    name="left_shoulder_roll_joint"
    type="revolute">
    <origin
      xyz="0 0 0.05"
      rpy="0 -1.5708 3.14" />
    <parent
      link="left_shoulder_pitch_link" />
    <child
      link="left_shoulder_roll_link" />
    <axis
      xyz="0 0 -1" />
    <limit
      lower="0"
      upper="0"
      effort="0"
      velocity="0" />
  </joint>
  <link
    name="left_arm_yaw_link">
    <inertial>
      <origin
        xyz="0 2.77555756156289E-17 0.1"
        rpy="0 0 0" />
      <mass
        value="2.7" />
      <inertia
        ixx="0.0052"
        ixy="0"
        ixz="0"
        iyy="0.0052"
        iyz="0"
        izz="0.0035935" />
    </inertial>
    <visual>
      <origin
        xyz="0 0 0"
        rpy="0 0 0" />
      <geometry>
        <mesh
          filename="../meshes/left_arm_yaw_link.STL" />
      </geometry>
      <material
        name="">
        <color
          rgba="1 1 1 1" />
      </material>
    </visual>
    <collision>
      <origin
        xyz="0 0 0"
        rpy="0 0 0" />
      <geometry>
        <mesh
          filename="../meshes/left_arm_yaw_link.STL" />
      </geometry>
    </collision>
  </link>
  <joint
    name="left_arm_yaw_joint"
    type="revolute">
    <origin
      xyz="0 -0.15 0"
      rpy="1.5708 -1.5708 0" />
    <parent
      link="left_shoulder_roll_link" />
    <child
      link="left_arm_yaw_link" />
    <axis
      xyz="0 0 -1" />
    <limit
      lower="0"
      upper="0"
      effort="0"
      velocity="0" />
  </joint>
  <link
    name="left_arm_pitch_link">
    <inertial>
      <origin
        xyz="5.55111512312578E-17 -0.09 0"
        rpy="0 0 0" />
      <mass
        value="2.7" />
      <inertia
        ixx="0.0052"
        ixy="0"
        ixz="0"
        iyy="0.0052"
        iyz="0"
        izz="0.0035935" />
    </inertial>
    <visual>
      <origin
        xyz="0 0 0"
        rpy="0 0 0" />
      <geometry>
        <mesh
          filename="../meshes/left_arm_pitch_link.STL" />
      </geometry>
      <material
        name="">
        <color
          rgba="1 1 1 1" />
      </material>
    </visual>
    <collision>
      <origin
        xyz="0 0 0"
        rpy="0 0 0" />
      <geometry>
        <mesh
          filename="../meshes/left_arm_pitch_link.STL" />
      </geometry>
    </collision>
  </link>
  <joint
    name="left_arm_pitch_joint"
    type="revolute">
    <origin
      xyz="0 0 0.2"
      rpy="-1.5708 0 0" />
      <!-- rpy="-1.5708 1.5708 0" /> -->
    <parent
      link="left_arm_yaw_link" />
    <child
      link="left_arm_pitch_link" />
    <axis
      xyz="0 0 1" />
    <limit
      lower="0"
      upper="0"
      effort="0"
      velocity="0" />
  </joint>
  <link
    name="right_shoulder_pitch_link">
    <inertial>
      <origin
        xyz="1.38777878078145E-17 1.11022302462516E-16 -0.05"
        rpy="0 0 0" />
      <mass
        value="2.7" />
      <inertia
        ixx="0.0052"
        ixy="0"
        ixz="0"
        iyy="0.0052"
        iyz="0"
        izz="0.0035935" />
    </inertial>
    <visual>
      <origin
        xyz="0 0 0"
        rpy="0 0 0" />
      <geometry>
        <mesh
          filename="../meshes/right_shoulder_pitch_link.STL" />
      </geometry>
      <material
        name="">
        <color
          rgba="1 1 1 1" />
      </material>
    </visual>
    <collision>
      <origin
        xyz="0 0 0"
        rpy="0 0 0" />
      <geometry>
        <mesh
          filename="../meshes/right_shoulder_pitch_link.STL" />
      </geometry>
    </collision>
  </link>
  <joint
    name="right_shoulder_pitch_joint"
    type="revolute">
    <origin
      xyz="0.010131 -0.14 0.33"
      rpy="1.5708 0 0" />
    <parent
      link="body_link" />
    <child
      link="right_shoulder_pitch_link" />
    <axis
      xyz="0 0 -1" />
    <limit
      lower="0"
      upper="0"
      effort="0"
      velocity="0" />
  </joint>
  <link
    name="right_shoulder_roll_link">
    <inertial>
      <origin
        xyz="-2.77555756156289E-17 -0.0499999999999998 0"
        rpy="0 0 0" />
      <mass
        value="2.7" />
      <inertia
        ixx="0.0052"
        ixy="0"
        ixz="0"
        iyy="0.0052"
        iyz="0"
        izz="0.0035935" />
    </inertial>
    <visual>
      <origin
        xyz="0 0 0"
        rpy="0 0 0" />
      <geometry>
        <mesh
          filename="../meshes/right_shoulder_roll_link.STL" />
      </geometry>
      <material
        name="">
        <color
          rgba="1 1 1 1" />
      </material>
    </visual>
    <collision>
      <origin
        xyz="0 0 0"
        rpy="0 0 0" />
      <geometry>
        <mesh
          filename="../meshes/right_shoulder_roll_link.STL" />
      </geometry>
    </collision>
  </link>
  <joint
    name="right_shoulder_roll_link"
    type="revolute">
    <origin
      xyz="0 0 0.05"
      rpy="3.1416 -1.5708 3.14" />
    <parent
      link="right_shoulder_pitch_link" />
    <child
      link="right_shoulder_roll_link" />
    <axis
      xyz="0 0 1" />
    <limit
      lower="0"
      upper="0"
      effort="0"
      velocity="0" />
  </joint>
  <link
    name="right_arm_yaw_link">
    <inertial>
      <origin
        xyz="2.77555756156289E-17 0 -0.1"
        rpy="0 0 0" />
      <mass
        value="2.7" />
      <inertia
        ixx="0.0052"
        ixy="0"
        ixz="0"
        iyy="0.0052"
        iyz="0"
        izz="0.0035935" />
    </inertial>
    <visual>
      <origin
        xyz="0 0 0"
        rpy="0 0 0" />
      <geometry>
        <mesh
          filename="../meshes/right_arm_yaw_link.STL" />
      </geometry>
      <material
        name="">
        <color
          rgba="1 1 1 1" />
      </material>
    </visual>
    <collision>
      <origin
        xyz="0 0 0"
        rpy="0 0 0" />
      <geometry>
        <mesh
          filename="../meshes/right_arm_yaw_link.STL" />
      </geometry>
    </collision>
  </link>
  <joint
    name="right_arm_yaw_link"
    type="revolute">
    <origin
      xyz="0 -0.15 0"
      rpy="1.5708 0 3.1416" />
    <parent
      link="right_shoulder_roll_link" />
    <child
      link="right_arm_yaw_link" />
    <axis
      xyz="0 0 1" />
    <limit
      lower="0"
      upper="0"
      effort="0"
      velocity="0" />
  </joint>
  <link
    name="right_arm_pitch_link">
    <inertial>
      <origin
        xyz="5.55111512312578E-17 -0.0899999999999999 -2.77555756156289E-17"
        rpy="0 0 0" />
      <mass
        value="2.7" />
      <inertia
        ixx="0.0052"
        ixy="0"
        ixz="0"
        iyy="0.0052"
        iyz="0"
        izz="0.0035935" />
    </inertial>
    <visual>
      <origin
        xyz="0 0 0"
        rpy="0 0 0" />
      <geometry>
        <mesh
          filename="../meshes/right_arm_pitch_link.STL" />
      </geometry>
      <material
        name="">
        <color
          rgba="1 1 1 1" />
      </material>
    </visual>
    <collision>
      <origin
        xyz="0 0 0"
        rpy="0 0 0" />
      <geometry>
        <mesh
          filename="../meshes/right_arm_pitch_link.STL" />
      </geometry>
    </collision>
  </link>
  <joint
    name="right_arm_pitch_joint"
    type="revolute">
    <origin
      xyz="0 0 -0.2"
      rpy="1.5708 0 -1.5708" />
      <!-- rpy="1.5708 -1.5708 -1.5708" /> -->
    <parent
      link="right_arm_yaw_link" />
    <child
      link="right_arm_pitch_link" />
    <axis
      xyz="0 0 -1" />
    <limit
      lower="0"
      upper="0"
      effort="0"
      velocity="0" />
  </joint>
</robot>